Traceback (most recent call last):
  File "/home/mattia/Documents/Git/super-duper-bot/.venv/lib/python3.11/site-packages/discord/ext/commands/core.py", line 235, in wrapped
    ret = await coro(*args, **kwargs)
          ^^^^^^^^^^^^^^^^^^^^^^^^^^^
  File "/home/mattia/Documents/Git/super-duper-bot/bin/music_cog.py", line 240, in play
    song = await self.search_yt(query)
           ^^^^^^^^^^^^^^^^^^^^^^^^^^^
  File "/home/mattia/Documents/Git/super-duper-bot/bin/music_cog.py", line 112, in search_yt
    cache_hit = await self.cache_cog.get_from_cache(item)
                      ^^^^^^^^^^^^^^^^^^^^^^^^^^^^^
AttributeError: 'NoneType' object has no attribute 'get_from_cache'

The above exception was the direct cause of the following exception:

Traceback (most recent call last):
  File "/home/mattia/Documents/Git/super-duper-bot/.venv/lib/python3.11/site-packages/discord/ext/commands/bot.py", line 1366, in invoke
    await ctx.command.invoke(ctx)
  File "/home/mattia/Documents/Git/super-duper-bot/.venv/lib/python3.11/site-packages/discord/ext/commands/core.py", line 1029, in invoke
    await injected(*ctx.args, **ctx.kwargs)  # type: ignore
    ^^^^^^^^^^^^^^^^^^^^^^^^^^^^^^^^^^^^^^^
  File "/home/mattia/Documents/Git/super-duper-bot/.venv/lib/python3.11/site-packages/discord/ext/commands/core.py", line 244, in wrapped
    raise CommandInvokeError(exc) from exc
discord.ext.commands.errors.CommandInvokeError: Command raised an exception: AttributeError: 'NoneType' object has no attribute 'get_from_cache'